[2025-07-21 18:19:50,204] ERROR daphne.server server.application_checker:297 - Exception inside application: No route found for path 'ws/system/'.
Traceback (most recent call last):
  File "/Users/mohsen/Desktop/fastapi/arbitrage/.venv/lib/python3.13/site-packages/django/contrib/staticfiles/handlers.py", line 101, in __call__
    return await self.application(scope, receive, send)
           ^^^^^^^^^^^^^^^^^^^^^^^^^^^^^^^^^^^^^^^^^^^^
  File "/Users/mohsen/Desktop/fastapi/arbitrage/.venv/lib/python3.13/site-packages/channels/routing.py", line 48, in __call__
    return await application(scope, receive, send)
           ^^^^^^^^^^^^^^^^^^^^^^^^^^^^^^^^^^^^^^^
  File "/Users/mohsen/Desktop/fastapi/arbitrage/.venv/lib/python3.13/site-packages/channels/sessions.py", line 44, in __call__
    return await self.inner(dict(scope, cookies=cookies), receive, send)
           ^^^^^^^^^^^^^^^^^^^^^^^^^^^^^^^^^^^^^^^^^^^^^^^^^^^^^^^^^^^^^
  File "/Users/mohsen/Desktop/fastapi/arbitrage/.venv/lib/python3.13/site-packages/channels/sessions.py", line 261, in __call__
    return await self.inner(wrapper.scope, receive, wrapper.send)
           ^^^^^^^^^^^^^^^^^^^^^^^^^^^^^^^^^^^^^^^^^^^^^^^^^^^^^^
  File "/Users/mohsen/Desktop/fastapi/arbitrage/.venv/lib/python3.13/site-packages/channels/auth.py", line 185, in __call__
    return await super().__call__(scope, receive, send)
           ^^^^^^^^^^^^^^^^^^^^^^^^^^^^^^^^^^^^^^^^^^^^
  File "/Users/mohsen/Desktop/fastapi/arbitrage/.venv/lib/python3.13/site-packages/channels/middleware.py", line 24, in __call__
    return await self.inner(scope, receive, send)
           ^^^^^^^^^^^^^^^^^^^^^^^^^^^^^^^^^^^^^^
  File "/Users/mohsen/Desktop/fastapi/arbitrage/.venv/lib/python3.13/site-packages/channels/routing.py", line 136, in __call__
    raise ValueError("No route found for path %r." % path)
ValueError: No route found for path 'ws/system/'.
[2025-07-21 18:19:52,211] ERROR daphne.server server.application_checker:297 - Exception inside application: No route found for path 'ws/prices/'.
Traceback (most recent call last):
  File "/Users/mohsen/Desktop/fastapi/arbitrage/.venv/lib/python3.13/site-packages/django/contrib/staticfiles/handlers.py", line 101, in __call__
    return await self.application(scope, receive, send)
           ^^^^^^^^^^^^^^^^^^^^^^^^^^^^^^^^^^^^^^^^^^^^
  File "/Users/mohsen/Desktop/fastapi/arbitrage/.venv/lib/python3.13/site-packages/channels/routing.py", line 48, in __call__
    return await application(scope, receive, send)
           ^^^^^^^^^^^^^^^^^^^^^^^^^^^^^^^^^^^^^^^
  File "/Users/mohsen/Desktop/fastapi/arbitrage/.venv/lib/python3.13/site-packages/channels/sessions.py", line 44, in __call__
    return await self.inner(dict(scope, cookies=cookies), receive, send)
           ^^^^^^^^^^^^^^^^^^^^^^^^^^^^^^^^^^^^^^^^^^^^^^^^^^^^^^^^^^^^^
  File "/Users/mohsen/Desktop/fastapi/arbitrage/.venv/lib/python3.13/site-packages/channels/sessions.py", line 261, in __call__
    return await self.inner(wrapper.scope, receive, wrapper.send)
           ^^^^^^^^^^^^^^^^^^^^^^^^^^^^^^^^^^^^^^^^^^^^^^^^^^^^^^
  File "/Users/mohsen/Desktop/fastapi/arbitrage/.venv/lib/python3.13/site-packages/channels/auth.py", line 185, in __call__
    return await super().__call__(scope, receive, send)
           ^^^^^^^^^^^^^^^^^^^^^^^^^^^^^^^^^^^^^^^^^^^^
  File "/Users/mohsen/Desktop/fastapi/arbitrage/.venv/lib/python3.13/site-packages/channels/middleware.py", line 24, in __call__
    return await self.inner(scope, receive, send)
           ^^^^^^^^^^^^^^^^^^^^^^^^^^^^^^^^^^^^^^
  File "/Users/mohsen/Desktop/fastapi/arbitrage/.venv/lib/python3.13/site-packages/channels/routing.py", line 136, in __call__
    raise ValueError("No route found for path %r." % path)
ValueError: No route found for path 'ws/prices/'.
